Workbook

Sheet 表格说明
A1: 中国银保监会银行业金融机构监管数据标准化规范 数据结构一览表说明
A2: 1. 标准化数据结构以表形式组织。一个或多个表归属于一个分类，每个表包含多个数据项。
A3: 2. 数据项已按表进行分类组合，通过使用最左侧导航按钮，可以展开或隐藏各表数据项，便于查看。
A4: 3. 数据结构备注中PK为监管部门作为唯一性约束的参考条件，含有多个PK的，表示联合主键的参考，并不作为主外键唯一性约束的要求，银行机构可根据数据实际入库情况作出调整。
A5: 4. “数据元说明”定义数据项的类型及长度的表示形式。
A6: 5. 数据项中备注“关联数据项：[表名].[数据项名]”表示该数据项取值的参考数据项。例如“关联数据项:机构信息表.内部机构号”表示该数据项应和“机构信息表”中的“内部机构号”数据项取值一致。
A7: 6. Cn 表示n个字符的固定长度，相应的字符长度由字符编码集确定。UTF-8的中文字符占3个字节。
A8: 7. C..n 表示最多为n个字符的可变长度。UTF-8的中文字符占3个字节。
A9: 8. I 表示整数可计算形式。
A10: 9. I..n 表示最多为n位的整数可计算形式。
A11: 10. Dw.d 表示十进制小数可计算形式，w表示包含小数点前后字符位在内的整个字段最多字符位数，d表示小数点后的最多字符位数。
A12: 11. F 表示任意长度浮点数。
A13: 12.本规范中涉及到的“明细科目编号”及“明细科目名称”均为该笔业务数据关联的主要会计科目名称，同一条数据涉及多个会计科目的仅报送该笔业务指向的主要会计科目，并不作为总分核对的分类指标。

Sheet 表结构总览
F1: 表编号 | G1: 报送模式 | H1: 报送要求 | I1: 修改说明
A2: 主题 | B2: 公共信息 | C2: 001
A3: 表名 | D3: JGXXB | E3: 机构信息表 | F3: 101 | G3: 全量表，报送截止采集日有效的数据以及与上一采集日期间失效的数据。 | H3: 本表报送银行机构或业务中心信息，业务中心包含管理机构、营业机构、内设机构、虚拟机构。对于营业机构、内设机构、虚拟机构，银行机构代码、金融许可证号等字段可以取上级机构或者本级实体机构对应的信息。境外机构也需要报送，根据实际情况无法填报的字段可以为空。子公司不必报送。机构永久关停、撤销等情况的，在报送最后状态的次月可不再报送。 | I3: 修改
D4: YGB | E4: 员工表 | F4: 102 | G4: 全量表，报送截止采集日有效的数据以及与上一采集日期间失效的数据。 | H4: 在职类正式/非正式员工需每月报送，非正式员工包括合同制、劳务派遣员工。员工状态转为离职、退休、开除、死亡、调出等的，在报送该员工最后状态的次月可不再报送。子公司员工不用报送，调动至子公司的员工按离职报送。董事、监事不用报送。 | I4: 修改
D5: GYB | E5: 柜员表 | F5: 103 | G5: 全量表，报送截止采集日有效的数据以及与上一采集日期间失效的数据。 | H5: 包含实体柜员和虚拟柜员。为虚拟柜员时，工号、银行机构代码等字段依业务实际填列或留为缺失值，如报送虚拟柜员，则通过“柜员类型”字段进行区分；柜员状态转为注销、无效等时，可在报送该条数据最终状态的次月不再报送。 | I5: 修改
D6: GWXXB | E6: 岗位信息表 | F6: 104 | G6: 全量表，报送截止采集日有效的数据以及与上一采集日期间失效的数据。 | H6: 银行机构内设立的所有岗位的相关信息，至少应包括核心和人力资源系统中的所有岗位信息。撤销的岗位于次月不再报送。 | I6: 修改
D7: JGGXB | E7: 机构关系表 | F7: 105 | G7: 全量表，报送截止采集日有效的数据以及与上一采集日期间失效的数据。 | H7: 机构关系表报送范围应包括所有进行账务处理的机构，至少应包括总行、分行、支行等实体机构和省级汇总、地市级汇总、法人汇总、分行汇总。会计全科目表中的机构在机构关系表中都需要报送，每次全量报送。 | I7: 修改
D8: GDXXB | E8: 股东信息表 | F8: 106 | G8: 全量表，报送截止采集日银行机构最新持股股东及持股比例等信息。 | H8: 本表应填报银行自身的股东。对于已上市银行，需填报持有或控制1%以上股份或表决权，及虽不足1%但对商业银行经营管理有重大影响的股东。未上市银行机构应报送所有的对公、个人股东信息。 | I8: 修改
B9: 客户信息 | C9: 002
D10: GRJCXXB | E10: 个人基础信息表 | F10: 201 | G10: 全量表，报送截止采集日有效的数据以及与上一采集日期间失效的数据。 | H10: 个人基础信息，包括本行客户及本行客户的担保、配偶、亲属关系所涉及到的个人客户信息。不再列为银行客户的数据不报送，存续业务中的所有个人信息都报送。。 | I10: 修改
D11: GRKHGXB | E11: 个人客户关系表 | F11: 202 | G11: 全量表，报送截止采集日有效的数据以及与上一采集日期间失效的数据。 | H11: 个人客户关系信息。所有的个人对个人的关系，包括担保、亲属、配偶等。对公客户为个人客户担保的关系也需在本表报送。本人为本人担保的关系不报送。 | I11: 修改
D12: DGKHXXB | E12: 对公客户信息表 | F12: 203 | G12: 全量表，报送截止采集日有效的数据以及与上一采集日期间失效的数据。 | H12: 银行机构所有对公客户的基本信息。集团类的虚拟客户的客户信息要上报，在法人代表一栏填集团客户。银行对企业分公司等非法人机构授信的，视同单一法人客户报送。以机构名义登记客户资料的个体工商户、私营业主应纳入本表填报范围。对于同业客户、政府机关、境外客户，若无法获取相关信息无法填报的数据项，允许为空。对于不再列为银行客户的数据不报送。 | I12: 修改
D13: DGKHCWXXB | E13: 对公客户财务信息表 | F13: 204 | G13: 增量表，报送本次采集日与上一采集日期间新增的数据。 | H13: 报送本月源系统中新收集的对公客户财务信息。对于非授信客户、负债类客户、离岸对公客户、机关事业单位、未达到税务部门建账标准的个体工商户等无需报送。 | I13: 新增
D14: JTKHB | E14: 集团客户表 | F14: 205 | G14: 全量表，报送截止采集日有效的数据以及与上一采集日期间失效的数据。 | H14: 报送在本行纳入集团授信的客户信息，包括供应链客户信息。以集团成员为最小粒度报送。同业集团客户信息无需报送。 | I14: 新增
D15: GLGXB | E15: 关联关系表 | F15: 206 | G15: 全量表，每期报送银行机构最新的客户关联关系信息，已失效的关联关系不报送。 | H15: 报送机构收集的对公客户以及填报机构自身的关联方和关系人信息，应包括主要股东、内部人、内部人近亲属、关联法人的董事、关联法人的监事、主要股东控股企业、内部人可施加重大影响的企业、供应链上下游、共同出资组建企业、担保关系、实际控制人、共同受同一关系人控制、集团成员、法定代表人、董事长（理事长）、监事长、总经理、财务主管等关联关系。对于填报机构自身的关联关系，需与机构自身认定的关联方和关系人一致，对于对公客户的关联关系，采取能采尽采的原则，包括但不限于授信尽职调查、外部数据源查询等途径获知的关联关系。同一关联方兼任或具有多重关联关系的，分多条进行报送。非授信客户、负债类客户不报送。 | I15: 修改
B16: 卡片信息 | C16: 003
D17: JJKXXB | E17: 借记卡信息表 | F17: 301 | G17: 全量表，报送截止采集日有效的数据以及与上一采集日期间失效的数据。 | H17: 个人和对公客户在银行机构开办的借记卡信息，指只能存取款而无法透支的卡片信息。本表需每月全量报送，当卡片状态为“注销”时，可在报送最后状态的次月不再报送。 | I17: 修改
D18: CZXXB | E18: 存折信息表 | F18: 302 | G18: 全量表，报送截止采集日有效的数据以及与上一采集日期间失效的数据。 | H18: 个人和对公客户在银行机构开办的存折信息。包括存折和存单。本表需每月全量报送，当存折状态为“注销”时，可在报送最后状态的次月不再报送。 | I18: 修改
D19: SDSHXXB | E19: 收单商户信息表 | F19: 303 | G19: 全量表，报送截止采集日有效的数据以及与上一采集日期间失效的数据。 | H19: 报送本行因线下线上收单业务而拓展的线下POS终端、线上终端以及二维码商户的信息。同一商户存在多个POS终端的，按多条报送。商户状态为“失效”或“注销”等状态的，在报送最后状态的次月可不再报送。 | I19: 新增
B20: 会计记账信息 | C20: 004
D21: ZZKJQKMB | E21: 总账会计全科目表 | F21: 401 | G21: 全量表，报送截止采集日有效的数据以及与上一采集日期间失效的数据。 | H21: 本表报送银行机构会计记账使用的所有会计科目及余额变动情况信息。余额为零的科目也要报送，不再使用的科目可以不报送。只报境内银行（不报子公司），包括总行、一级分行、二级分行、一级支行（最多报4级）。如果发生新老科目变更，在当期数据中报送最新科目即可。每月最后一天数据应同时报送按月和按日为周期的会计数据，每年最后一天数据应同时报送按日、按月、季、半年、年为周期的会计数据，以此类推。只报送人民币和本外币合计。 | I21: 修改
D22: NBKMDZB | E22: 内部科目对照表 | F22: 402 | G22: 全量表，报送截止采集日有效的数据以及与上一采集日期间失效的数据。 | H22: 本表报送总账会计全科目的上下级对应关系，以会计科目为最小粒度报送。内部科目对照表由法人机构统一确定，分支机构按同一内容报送。报送科目必须与当期《总账会计全科目表》中的科目一致。此表首次采集为全量采集，后续采集如有变化，需全量报送。 | I22: 修改
D23: GRHQCKFHZ | E23: 个人活期存款分户账 | F23: 403 | G23: 全量表，报送截止采集日有效的数据以及与上一采集日期间失效的数据。 | H23: 指金融机构吸收的所有以个人名义存入的活期存款。报送范围：参照1104报表G01_III中[2.2.1个人活期存款]除去信用卡溢缴款部分填报。个体工商户的存款属于个人存款。信用卡业务不在本表中填报。以活期存款账号为最小颗粒报送，如账户注销或终结，在报送该账户最终状态后的次月可不再报送。 | I23: 修改
D24: GRHQCKFHZMX | E24: 个人活期存款分户账明细记录 | F24: 404 | G24: 增量表，报送本次采集日与上一采集日期间新增的数据。 | H24: 除计息、扣利息税外，所有影响个人活期存款账户余额变动的交易信息，不包括查询交易。
D25: GRDQCKFHZ | E25: 个人定期存款分户账 | F25: 405 | G25: 全量表，报送截止采集日有效的数据以及与上一采集日期间失效的数据。 | H25: 个人客户在银行机构开设的除活期存款账户以外其他所有以个人名义划入的存款账户信息，包括定期、定活两便、通知存款、机构性存款等多种非活期的账户信息。报送范围：参照1104报表G01_III[2.2 个人存款]-[2.2.1 个人活期存款]口径填报。个体工商户的存款属于个人存款。信用卡业务不在本表中填报。以定期存款账号为最小颗粒报送，如账户注销或终结，在报送该账户最终状态后的次月可不再报送。 | I25: 修改
D26: GRDQCKFHZMX | E26: 个人定期存款分户账明细记录 | F26: 406 | G26: 增量表，报送本次采集日与上一采集日期间新增的数据。 | H26: 除计息、扣利息税外，所有影响个人定期存款账户余额变动的交易信息，不包括查询交易。
D27: DGHQCKFHZ | E27: 对公活期存款分户账 | F27: 407 | G27: 全量表，报送截止采集日有效的数据以及与上一采集日期间失效的数据。 | H27: 指银行机构吸收的除个人以外的机构（包括企业、事业单位、机关、社会团体、同业机构等）开立的所有活期存款账户信息。报送范围：参照1104报表G01_III中[2.1.1单位活期存款]以及财政部门、金融机构（同业）活期存款填报。按照人行账户管理办法划分标准，包括所有对公类活期账户余额（含同业账户）。以活期存款账号为最小颗粒报送，如账户注销或终结，在报送该账户最终状态后的次月可不再报送。 | I27: 修改
D28: DGHQCKFHZMX | E28: 对公活期存款分户账明细记录 | F28: 408 | G28: 增量表，报送本次采集日与上一采集日期间新增的数据。 | H28: 所有影响对公活期存款账户余额变动的交易信息，不包括查询交易。不包括计息和扣利息税记录。
D29: DGDQCKFHZ | E29: 对公定期存款分户账 | F29: 409 | G29: 全量表，报送截止采集日有效的数据以及与上一采集日期间失效的数据。 | H29: 指银行机构吸收的除个人以外的机构（包括企业、财政部门、社保基金、部队、住房公积金、社会团体、同业机构等）开立的，除活期存款以外的其他所有存款账户信息。报送范围：参照1104报表G01_III[2.1 单位存款] - [2.1.1单位活期存款] + 财政部门、金融机构除活期外存款。包括对公定期、定活两便，以及对公协议、协定、结构性存款、同业存放、吸收的保险公司存放款、社会保障基金、2009年1月1日前签署的邮政储蓄机构等的协议存款的定期存款分户账信息。以定期存款账号为最小颗粒报送，如账户注销或终结，在报送该账户最终状态后的次月可不再报送。 | I29: 修改
D30: DGDQCKFHZMX | E30: 对公定期存款分户账明细记录 | F30: 410 | G30: 增量表，报送本次采集日与上一采集日期间新增的数据。 | H30: 所有影响对公定期存款账户余额变动的交易信息，不包括查询交易。不包括计息和扣利息税记录。
D31: NBFHZ | E31: 内部分户账 | F31: 411 | G31: 全量表，报送截止采集日有效的数据以及与上一采集日期间失效的数据。 | H31: 根据会计核算科目，除机关财务账、单列账之外的科目原则上都归入内部账采集；单列账、机关财务账不报送，资本账户需要报送。以内部分户账号为最小颗粒报送，如账户注销或终结，在报送该账户最终状态后的次月可不再报送。交易与核算分离的机构，应根据总账科目中划分出对应内部分户账性质的科目，自定义内部分户账号进行报送。 | I31: 修改
D32: NBFHZMX | E32: 内部分户账明细记录 | F32: 412 | G32: 增量表，报送本次采集日与上一采集日期间新增的数据。 | H32: 根据会计核算科目，除机关财务账、单列账之外的科目原则上都归入内部账采集；机关财务账、单列账不需要在此表报送，报送至信用卡和其余六个对公/个人分户账中；资本账户需要报送。
D33: GRXDFHZ | E33: 个人信贷分户账 | F33: 413 | G33: 全量表，报送截止采集日有效的数据以及与上一采集日期间失效的数据。 | H33: 本表为开展各项表内、表外信贷业务，以个人名义在银行机构所开立的信贷账户信息。报送范围：1104报表G01_VII[2.21 个人贷款(不含个人经营性贷款)] + [4.个人经营性贷款] - [2.21.1信用卡] + G01_I_2《委托贷款投向统计表》[2.21个人贷款(不含个人经营性贷款)] 。个体工商户、私营业主以营业执照等证件开立的对公账户也计入本表。表内个人贷款不报送信用卡业务。表外业务只报送委托贷款（非现金管理项下），其他不报送。以信贷借据号为最小粒度报送，借据结清、核销或转让的，可在报送最后状态的次月不再报送。账户状态为“销户”时，也可于次月不再报送。 | I33: 修改
D34: GRXDFHZMX | E34: 个人信贷分户账明细记录 | F34: 414 | G34: 增量表，报送本次采集日与上一采集日期间新增的数据。 | H34: 所有影响个人信贷账户余额或利息变动的交易信息，包括还本、还息，不包括查询交易。贷款核销或者转让（包括资产证券化）也应该在本表体现：明细科目填报本金科目，交易金额为核销或转让前本金余额，余额为0，交易对手填写借款人自身信息，摘要中标明核销或者转让交易。 | I34: 修改
D35: DGXDFHZ | E35: 对公信贷分户账 | F35: 415 | G35: 全量表，报送截止采集日有效的数据以及与上一采集日期间失效的数据。 | H35: 除个人以外的各类机构（包括企业、机关团体、社保基金、部队、住房公积金）为开展各项信贷业务，在银行机构所开立的信贷账户信息。报送范围：1104报表G01_VII[1.各项贷款] - [2.21 个人贷款(不含个人经营性贷款)] - [4.个人经营性贷款] + G01_I_2《委托贷款投向统计表》[1.委托贷款合计（非现金管理项下）] - G01_I_2[2.21个人贷款(不含个人经营性贷款)]。表外业务只报送委托贷款（非现金管理项下），其他不报送。对于票据贴现和买断式转贴现，可以填报为信贷分户账号=信贷借据号=票据号码；对于其他若没有对应信贷分户账号的业务，可以填报为信贷分户账号=信贷借据号=业务编号。以信贷借据号为最小粒度报送，借据结清、核销或转让的，可在报送最后状态的次月不再报送。账户状态为“销户”时，也可于次月不再报送。 | I35: 修改
D36: DGXDFHZMX | E36: 对公信贷分户账明细记录 | F36: 416 | G36: 增量表，报送本次采集日与上一采集日期间新增的数据。 | H36: 所有影响对公信贷账户余额或利息变动的交易信息，包括还本、还息，不包括查询交易。贷款核销或者转让（包括资产证券化）也应该在本表体现：明细科目填报本金科目，交易金额为核销或转让前本金余额，余额为0，交易对手填写借款人自身信息，摘要中标明核销或者转让交易。 | I36: 修改
B37: 各项贷款 | C37: 005
D38: XDHTB | E38: 信贷合同表 | F38: 501 | G38: 全量表，报送截止采集日有效的数据以及与上一采集日期间失效的数据。 | H38: 报送范围：按照1104报表G01_VII[1.各项贷款] - G01_VII[2.21.1信用卡] + G01_I_2《委托贷款投向统计表》[1.委托贷款合计（非现金管理项下）]口径填报。报送个人贷款、对公贷款、票据贴现、买断式转贴现、贸易融资业务、融资租赁业务、委托贷款（非现金管理项下）对应的业务合同，以及各项垫款对应的原业务合同。委托贷款中现金管理项下委托贷款不报送，其他表外业务不报送。信用卡业务不报送。对于票据贴现和买断式转贴现，可以填报为信贷合同号=信贷借据号=票据号码；对于其他若没有对应合同号的业务，可以填报为信贷合同号=信贷借据号=业务编号。已撤销、失效、终结的合同在报送合同最后状态的次月可不再报送。 | I38: 修改
D39: GRXDYWJJB | E39: 个人信贷业务借据表 | F39: 502 | G39: 全量表，报送截止采集日有效的数据以及与上一采集日期间失效的数据。 | H39: 所有以个人名义在信贷业务中签订的借据信息。报送范围：按照1104报表G01_VII[2.21 个人贷款(不含个人经营性贷款)] + [4.个人经营性贷款] - [2.21.1信用卡] + G01_I_2《委托贷款投向统计表》[2.21个人贷款(不含个人经营性贷款)] 填报口径。委托贷款中现金管理项下委托贷款不报送，其他表外业务不报送。信用卡业务不报送。对于票据贴现和买断式转贴现，可以填报为信贷合同号=信贷借据号=票据号码；对于其他若没有对应借据号的业务，可以填报为信贷合同号=信贷借据号=业务编号。借据状态为结清、核销、转让的可在报送最后状态的次月不再报送。 | I39: 修改
D40: DGXDYWJJB | E40: 对公信贷业务借据表 | F40: 503 | G40: 全量表，报送截止采集日有效的数据以及与上一采集日期间失效的数据。 | H40: 所有以机构名义在信贷业务中签订的借据信息。报送范围：1104报表G01_VII[1.各项贷款] - [2.21 个人贷款(不含个人经营性贷款)] - [4.个人经营性贷款] + G01_I_2《委托贷款投向统计表》[1.委托贷款合计（非现金管理项下）] - G01_I_2[2.21个人贷款(不含个人经营性贷款)]。委托贷款中现金管理项下委托贷款不报送，其他表外业务不报送。对于票据贴现和买断式转贴现，可以填报为信贷合同号=信贷借据号=票据号码，信用证业务可填报信用证号；对于其他若没有对应借据号的业务，可以填报为信贷合同号=信贷借据号=业务编号。借据状态为结清、核销、转让的可在报送最后状态的次月不再报送。 | I40: 修改
...

Sheet 数据元说明
A2: 数据元说明
A4: 分类 | B4: 数据元编码 | C4: 数据元名称 | D4: 数据元英文 | E4: 数据元说明 | F4: 格式
A6: 公共信息 | B6: 001
B7: 001001 | C7: 名称 | D7: Name | E7: 名称应与公章所使用的名称完全一致。银行机构以银保监会金融机构许可证登记名称为准。无独立金融机构许可证的机构，可在本名称中体现出机构特征。第三方支付平台填报第三方支付平台名称。 客户名称按照客户的不同类型按如下标准填报。 （1）集团客户，填报银行对该集团授信采用的集团客户名称。视同集团客户填报的供应链融资填报核心企业客户名称。 （2）单一法人客户，经有关部门批准正式使用的全称，与公章所使用的名称完全一致。视同单一法人客户填报的分公司，填报分公司全称，与分公司公章所使用的名称完全一致。客户是境内涉密机构的，客户名称填报为“*********”。 （3）同业客户，经有关部门批准正式使用的客户全称，与客户公章所使用的名称完全一致。 （4）自然人，与有效证件上的姓名一致。 （5）境外客户，客户名称应尽量以中文翻译填报，如没有可填报英文名称。 | F7: C..400
B8: 001002 | C8: 是否标志 | D8: Yes or No | E8: 是，否。 | F8: C3
B9: 001003 | C9: 比例 | D9: Ratio | E9: 百分比为单位，即1/100，保留两位小数。如4.5%则填报为4.50。 | F9: D20.2
B10: 001004 | C10: 比例（精） | D10: Accurate rate | E10: 百分比为单位，即1/100，保留六位小数。4.123456%则填报为4.123456。 | F10: D20.6
B11: 001005 | C11: 日期 | D11: Date | E11: YYYYMMDD，默认值99991231。 | F11: C8
B12: 001006 | C12: 年月 | D12: Year & Month | E12: YYYYMM，默认值999912。 | F12: C6
B13: 001007 | C13: 时间 | D13: Time | E13: 24小时制时间，精确到秒。hhmmss，默认值000000。 | F13: C6
B14: 001008 | C14: 地址 | D14: Address | E14: 中文描述。个人填报个人住址。机构填报有关部门批准的有效证件上登记的地址。参照《企业法人营业执照》中的注册地填报，要写明省（区、市）、地（区、市、州、盟）、县（区、市、旗）。境外机构及境内涉密机构不填报。 | F14: C..400
B15: 001009 | C15: 电话 | D15: Tel. | E15: 手机号码或者区号-固定电话号码。 | F15: C..30
B16: 001010 | C16: 银行机构代码 | D16: Bank code | E16: 12位人行支付行号或SWIFT行号。 | F16: C..30
B17: 001011 | C17: 金融许可证号 | D17: Financial license number | E17: 金融许可证机构编码编制规则（试行） 一、机构编码结构 机构编码由大写英文字母和数字组成，共15位。分六个部分，分别是机构类型代码、机构代码、组织类别代码、发证机关代码、地址代码、顺序代码，从左至右顺序排列，如下表所示。 二、机构编码含义 （一）第［一］位是机构类型代码，用大写英文字母表示。 A-政策性银行 B-商业银行 C-农村合作银行 D-城市信用社 E-农村信用社 F-资金互助社 J-金融资产管理公司 K-信托公司 L-财务公司 M-金融租赁公司 N-汽车金融公司 P-货币经纪公司 Q-贷款公司 Z-其他类金融机构 新增机构类型时，根据需要确定机构类型代码。 （二）第［二］位至第［五］位是机构代码，用数字表示。 1.每个法人机构指定唯一的代码，由计算机系统按照规则自动生成。除农村信用社、资金互助社、贷款公司（E、F、Q类机构）外，全国统一编码。E、F、Q类机构在省（自治区、直辖市）范围内统一编码。 2.新设立的机构依照所属机构类型顺序排列。 机构代码编码示例如下： A-政策性银行 0001-国家开发银行 …… B-商业银行 0001-中国工商银行股份有限公司 …… C-农村合作银行 0001-天津大港农村合作银行 …… D-城市信用社 0001-邯郸市城市信用社股份有限公司 …… E-农村信用社天津市 0001-天津市宝坻区农村信用合作联社 …… 新疆维吾尔自治区 0001-新疆维吾尔自治区农村信用社联合社 …… F-资金互助社 吉林省 0001-吉林省梨树县闰家村百信农村资金互助社 …… 青海省 0001-青海省乐都县雨润镇兴乐农村资金互助社 …… J-金融资产管理公司 0001-中国华融资产管理公司 …… K-信托投资公司 0001-中诚信托投资有限责任公司 …… L-财务公司 0001-中海石油财务有限责任公司 …… M-金融租赁公司 0001-中国外贸金融租赁公司 …… N-汽车金融公司 0001-大众汽车金融（中国）有限公司 …… P-货币经纪公司 0001-上海国利货币经纪有限公司 …… Q-贷款公司四川省 0001-四川省仪陇县惠民贷款有限责任公司 …… 新疆维吾尔自治区 0001- …… Z-其他类金融机构 0001-中央国债登记结算有限责任公司 …… （三）第〔六〕位是组织类别代码，用大写英文字母表示。 机构类型不同，组织类别代码的含义不同。定义如下： 1.A-政策性银行 H-总行 G-总行营业部 H-级分行 K-一级分行营业部 M-二级分行 S-支行 X-其他分支机构 2.B-商业银行 H-总行 G-总行营业部、专营机构 B-一级分行 K-一级分行营业部 L-二级分行 M-直属支行 N-二级分行营业部 S-支行 U-分理处、办事处、营业所 V-储蓄所 X-其他分支机构 3.C-农村合作银行 H-总行 S-支行 U-分理处 V-储蓄所 X-其他分支机构 4.D-城市信用社 H-法人 S-分社、营业部 X-其他分支机构 5.E-农村信用社 H-省（自治区、直辖市）联合社 B-地（市）联合社、联社 S-县（市）联合社、联社、合作社（县级） T-信用合作社 U-信用社、分社 V-储蓄所 X-其他分支机构 6.F-资金互助社 H-法人 7.J-金融资产管理公司 H-总公司 B-办事处 X-其他分支机构 8.K-信托公司 H-法人 9.N-汽车金融公司 H-法人 10.L-财务公司 H-总公司 B-分公司 X-其他分支机构 11.M-金融租赁公司 H-总公司 B-分公司 X-其他分支机构 12.P-货币经纪公司 H-总公司 B-分公司 X-其他分支机构 13.Q-贷款公司 H-总公司 B-分公司 X-其他分支机构 14.Z-其他类金融机构 Z类机构组织类别代码编码方法参照以上规则。 新增机构类型时，参照以上规则，根据实际情况定义其组织类别代码。 （四）第〔七〕位是发证机关代码，用数字表示。 1-银保监会 2-银监局 3-银监分局 （五）第〔八〕位至第〔十一〕是地址代码，用数字表示。按照《中华人民共和国行政区划代码》 （GB/T2260），取市（地区、自治州、盟）、直辖市行政区划代码前四位，作为地址代码。 地址代码示例如下：1100表示北京市，1200表示天津市，1301表示石家庄市，…… （六）第〔十二〕位至第〔十五〕位是顺序代码，用数字表示。机构类型代码、机构代码、组织类别代码、发证机关代码和地址代码相同的机构按照制发金融许可证的顺序编码。 三、机构编码的编制规则 编制机构编码时，按照从左至右的顺序依次确定机构类型代码、机构代码、组织类别代码、发证机关代码、地址代码、顺序代码，由计算机自动生成。 为了保证机构编码的唯一性，以利于电子计算机较长时间地存储数据，因行政许可变更需换发金融许可证，涉及机构编码变更的，原机构编码不再使用.金融机构终止的，机构编码不再使用。注销开业许可收回金融许可证的，机构编码不再使用。 | F17: C..30
B18: 001012 | C18: 内部机构号 | D18: Inner organization number | E18: 银行内部机构号。应具有标识机构的唯一性。 | F18: C..30
... B46: 001040 | C46: 备注 | D46: Remark | E46: 银行自定义。 | F46: C..600
A47: 客户信息 | B47: 002
B48: 002001 | C48: 客户统一编号 | D48: Customer number | E48: 银行自定义的唯一识别客户的标识。供应链融资的填写供应链融资编码。 | F48: C..60
B49: 002002 | C49: 证件类别 | D49: Document type | E49: 同业客户：银行机构代码，金融许可证号，SWIFT编码，其他-XX。 对公客户：统一社会信用代码，组织机构代码，营业执照（工商注册号），公司注册证书，全球法人识别码，其他-XX。 个人客户：居民身份证，军官证，文职干部证，警官证，士兵证，户口簿，临时身份证，其他有效通行旅行证件，护照，学生证，无证件，其他-XX。 无法以枚举类型填报的，以“其他-XX”报送，其中“XX”为银行自定义类型。 对公客户优先填报统一社会信用代码，没有统一社会信用代码的对公客户填报组织机构代码。组织机构代码、统一社会信用代码均没有的可以填报客户提供的批文文号、开户主证件、上级机构统一社会信用代码等，以“其他-XX”填报。 | F49: C..60
B50: 002003 | C50: 证件号码 | D50: Document number | E50: 与证件类别对应的证件号码。涉及个人身份证件时需按照本规范给定规则进行脱敏处理。 | F50: C..70
B51: 002004 | C51: 国籍 | D51: Nationality | E51: 参照《GB/T 2659-2000 世界各国和地区名称》，填报中文名称。 | F51: C..60
B52: 002005 | C52: 民族 | D52: Ethnicity | E52: 国家认可的在公安户籍管理部门正式登记注册的客户所属民族的名称。 | F52: C..30
B53: 002006 | C53: 性别 | D53: Gender | E53: 男，女。 | F53: C3
B54: 002007 | C54: 学历 | D54: Education degree | E54: 参照《GB/T 4658-2006 学历代码》填写中文描述或中文字典。 | F54: C..30
B55: 002008 | C55: 职业 | D55: Career | E55: 中文描述或中文字典，银行自定义。 | F55: C..80
B56: 002009 | C56: 婚姻情况 | D56: Marriage | E56: 未婚，已婚，初婚，再婚，复婚，丧偶，离异。 | F56: C..6
B57: 002010 | C57: 上黑名单原因 | D57: Reason of on black list | E57: 中文字典或中文描述，银行自定义。 | F57: C..400
B58: 002011 | C58: 单位性质 | D58: Unit property | E58: 国有企业、民营企业、政府机关、事业单位、社会团体、境外机构、其他-银行自定义。无法以枚举类型填报的，以“其他-XX”填报，其中“XX”为银行自定义类型。 | F58: C..60
B59: 002012 | C59: 社会关系 | D59: Social relationship | E59: 配偶，父母，子女，亲属关系，朋友，同事，合作伙伴，离异原配偶，其他-银行自定义。无法以枚举类型填报的，以“其他-XX”填报，其中“XX”为银行自定义类型。 | F59: C..60
... B75: 002028 | C75: 财务报表编号 | D75: Financial statement number | E75: 唯一标识财务报表的编号，银行自定义。 | F75: C..30
A76: 账户 | B76: 003
B77: 003001 | C77: 账号 | D77: Account number | E77: 系统内最细一级的账号，无唯一性约束，不需要和序号、子序号等做拼接。 | F77: C..60
B78: 003002 | C78: 会计科目编号 | D78: Subject number of general ledger accounting | E78: 机构实际使用的总账会计科目编码。 | F78: C..200
B79: 003003 | C79: 会计科目名称 | D79: Subject name of general ledger accounting | E79: 机构实际使用的总账会计科目编码对应的名称。 | F79: C..200
B80: 003004 | C80: 会计科目级次 | D80: Subject grade of general ledger accounting | E80: 总账会计科目编号在科目结构中所对应的级次。 | F80: I..2
B81: 003005 | C81: 会计科目大类 | D81: Account category | E81: 资产、负债、所有者权益、损益、资产负债共同类、表外、其他。 | F81: C..30
B82: 003006 | C82: 会计科目子类 | D82: Account sub category | E82: 资产类业务子类：1现金，2贵金属，3存放中央银行款项，4存放同业款项，5应收利息，6贷款，7贸易融资，8贴现及买断式转贴现，9其他贷款，10拆放同业，11其他应收款，12投资，13买入返售资产，14长期待摊费用，15固定资产原价，16减：累计折旧，17固定资产净值，18固定资产清理，19在建工程，20无形资产，21抵债资产，22递延所得税资产，23其他资产，24各项资产减值损失准备。 负债类业务子类：25单位存款，26储蓄存款，27向中央银行借款，28同业存放款项，29同业拆入，30卖出回购款项，31汇出汇款，32应解汇款，33存入保证金，34应付利息，35应交税费，36应付职工薪酬，37应付福利费，38应付股利，39其他应付款，40预提费用，41递延收益，42预计负债，43转贷款资金，44应付债券，45其他负债，46递延所得税负债。 所有者权益类业务子类：47实收资本，48资本公积，49盈余公积，50一般风险准备，51信托赔偿准备，52未分配利润，53其他综合收益，54其他权益工具。 损益类业务子类：55利息收入，56利息支出，57手续费及佣金收入，58手续费及佣金支出，59投资损益，60公允价值变动损益，61汇兑损益，62资产处置损益，63其他业务收入，64营业支出，65营业外收入，66营业外支出，67资产减值损失，68所得税，69少数股东损益。 表外业务类别：70承兑汇票，71跟单信用证，72保函，73信用风险仍在银行的销售与购买协议，74其他担保类业务，75可随时无条件撤销的贷款承诺，76不可无条件撤销的贷款承诺，77未使用的信用卡授信额度，78其他承诺，79发行非保本理财产品，80委托贷款，81委托投资，82代理代销业务，83资产托管，84其他金融资产服务业务，85金融衍生品类。 | F82: C..200
B83: 003007 | C83: 统计科目编号 | D83: Statistic subject number | E83: 参照《中国人民银行关于建立金融基础数据统计制度的通知》（银发[2020]164号）中的统计指标编码填报。如： 单位存款：单位活期存款-12MG4/22MG4；单位定期存款-12MGB/22MGB；单位通知存款-12MGI/22MGI；单位协议存款-12MGR/22MGR；单位协定存款-12MH4/22MH4；单位保证金存款-12MHB/22MHB；单位结构性存款-12MHI/22MHI 个人存款：个人活期存款-12MI2/22MI2；个人定期存款-12MI4/22MI4；个人定活两便存款-12MI6/22MI6；个人通知存款-12MI8/22MI8；个人协议存款是A1411/2411 12MIA/22MIA ；个人协定存款-12MIC/22MIC；个人保证金存款-12MIE/22MIE；个人结构性存款-12MIG/22MIG 普通贷款：单位经营贷款-12M3H/22M3H；单位固定资产贷款-12M3I/22M3I；个人贷款-12M36/22M36；对非居民贷款-12M4E/22M4E ；单位经营贷款-12M5C/22M5C ；单位固定资产贷款-12M5D/22M5D；一般委托贷款-34R03 | F83: C..20
B84: 003008 | C84: 统计科目名称 | D84: Statistic subject name | E84: 参照《中国人民银行关于建立金融基础数据统计制度的通知》（银发[2020]164号）中的统计指标名称填报。如： 单位存款：单位活期存款-12MG4/22MG4；单位定期存款-12MGB/22MGB；单位通知存款-12MGI/22MGI；单位协议存款-12MGR/22MGR；单位协定存款-12MH4/22MH4；单位保证金存款-12MHB/22MHB；单位结构性存款-12MHI/22MHI 个人存款：个人活期存款-12MI2/22MI2；个人定期存款-12MI4/22MI4；个人定活两便存款-12MI6/22MI6；个人通知存款-12MI8/22MI8；个人协议存款是A1411/2411 12MIA/22MIA ；个人协定存款-12MIC/22MIC；个人保证金存款-12MIE/22MIE；个人结构性存款-12MIG/22MIG 普通贷款：单位经营贷款-12M3H/22M3H；单位固定资产贷款-12M3I/22M3I；个人贷款-12M36/22M36；对非居民贷款-12M4E/22M4E ；单位经营贷款-12M5C/22M5C ；单位固定资产贷款-12M5D/22M5D；一般委托贷款-34R03 | F84: C..120
B85: 003009 | C85: 借贷标志 | D85: D.C. flag | E85: 借，贷，借贷并列。 | F85: C..12
...

Sheet 数据结构
A2: 中国银保监会银行业金融机构监管数据标准化规范（2021版）
A4: 分类 | B4: 分类编号 | C4: 传输文件名称 | D4: 表名 | E4: 表编号 | F4: 数据项名称 | G4: 数据项代码 | H4: 数据项编号 | I4: 数据元 | J4: 数据元编码 | K4: 数据元说明 | L4: 格式 | M4: 备注 | N4: 变更类型 | O4: 变更规范列 | P4: 变更说明
A6: 公共信息 | B6: 001
C7: JGXXB | D7: 机构信息表 | E7: 101 | M7: =INDEX(表结构总览!E:H,MATCH(D7,表结构总览!E:E,0),4) -> 本表报送银行机构或业务中心信息，业务中心包含管理机构、营业机构、内设机构、虚拟机构。对于营业机构、内设机构、虚拟机构，银行机构代码、金融许可证号等字段可以取上级机构或者本级实体机构对应的信息。境外机构也需要报送，根据实际情况无法填报的字段可以为空。子公司不必报送。机构永久关停、撤销等情况的，在报送最后状态的次月可不再报送。 | N7: 修改 | O7: 备注
F8: 银行机构代码 | G8: YHJGDM | H8: 10101 | I8: 银行机构代码 | J8: =INDEX(数据元说明!A:F,MATCH(I8,数据元说明!C:C,0),2) -> 001010 | K8: =INDEX(数据元说明!A:F,MATCH(I8,数据元说明!C:C,0),5) -> 12位人行支付行号或SWIFT行号。 | L8: =INDEX(数据元说明!A:F,MATCH(I8,数据元说明!C:C,0),6) -> C..30 | M8: 需填报人行大小额支付系统中登记的“人行支付行号”；允许多个内部机构号对应同一个“人行支付行号”；该字段不可为空，内设机构、虚拟机构等无“人行支付行号”的，填报上一级机构的“人行支付行号”。
F9: 内部机构号 | G9: NBJGH | H9: 10102 | I9: 内部机构号 | J9: =INDEX(数据元说明!A:F,MATCH(I9,数据元说明!C:C,0),2) -> 001012 | K9: =INDEX(数据元说明!A:F,MATCH(I9,数据元说明!C:C,0),5) -> 银行内部机构号。应具有标识机构的唯一性。 | L9: =INDEX(数据元说明!A:F,MATCH(I9,数据元说明!C:C,0),6) -> C..30 | M9: PK
F10: 金融许可证号 | G10: JRXKZH | H10: 10103 | I10: 金融许可证号 | J10: =INDEX(数据元说明!A:F,MATCH(I10,数据元说明!C:C,0),2) -> 001011 | K10: =INDEX(数据元说明!A:F,MATCH(I10,数据元说明!C:C,0),5) -> 金融许可证机构编码编制规则（试行） 一、机构编码结构 机构编码由大写英文字母和数字组成，共15位。分六个部分，分别是机构类型代码、机构代码、组织类别代码、发证机关代码、地址代码、顺序代码，从左至右顺序排列，如下表所示。 二、机构编码含义 （一）第［一］位是机构类型代码，用大写英文字母表示。 A-政策性银行 B-商业银行 C-农村合作银行 D-城市信用社 E-农村信用社 F-资金互助社 J-金融资产管理公司 K-信托公司 L-财务公司 M-金融租赁公司 N-汽车金融公司 P-货币经纪公司 Q-贷款公司 Z-其他类金融机构 新增机构类型时，根据需要确定机构类型代码。 （二）第［二］位至第［五］位是机构代码，用数字表示。 1.每个法人机构指定唯一的代码，由计算机系统按照规则自动生成。除农村信用社、资金互助社、贷款公司（E、F、Q类机构）外，全国统一编码。E、F、Q类机构在省（自治区、直辖市）范围内统一编码。 2.新设立的机构依照所属机构类型顺序排列。 机构代码编码示例如下： A-政策性银行 0001-国家开发银行 …… B-商业银行 0001-中国工商银行股份有限公司 …… C-农村合作银行 0001-天津大港农村合作银行 …… D-城市信用社 0001-邯郸市城市信用社股份有限公司 …… E-农村信用社天津市 0001-天津市宝坻区农村信用合作联社 …… 新疆维吾尔自治区 0001-新疆维吾尔自治区农村信用社联合社 …… F-资金互助社 吉林省 0001-吉林省梨树县闰家村百信农村资金互助社 …… 青海省 0001-青海省乐都县雨润镇兴乐农村资金互助社 …… J-金融资产管理公司 0001-中国华融资产管理公司 …… K-信托投资公司 0001-中诚信托投资有限责任公司 …… L-财务公司 0001-中海石油财务有限责任公司 …… M-金融租赁公司 0001-中国外贸金融租赁公司 …… N-汽车金融公司 0001-大众汽车金融（中国）有限公司 …… P-货币经纪公司 0001-上海国利货币经纪有限公司 …… Q-贷款公司四川省 0001-四川省仪陇县惠民贷款有限责任公司 …… 新疆维吾尔自治区 0001- …… Z-其他类金融机构 0001-中央国债登记结算有限责任公司 …… （三）第〔六〕位是组织类别代码，用大写英文字母表示。 机构类型不同，组织类别代码的含义不同。定义如下： 1.A-政策性银行 H-总行 G-总行营业部 H-级分行 K-一级分行营业部 M-二级分行 S-支行 X-其他分支机构 2.B-商业银行 H-总行 G-总行营业部、专营机构 B-一级分行 K-一级分行营业部 L-二级分行 M-直属支行 N-二级分行营业部 S-支行 U-分理处、办事处、营业所 V-储蓄所 X-其他分支机构 3.C-农村合作银行 H-总行 S-支行 U-分理处 V-储蓄所 X-其他分支机构 4.D-城市信用社 H-法人 S-分社、营业部 X-其他分支机构 5.E-农村信用社 H-省（自治区、直辖市）联合社 B-地（市）联合社、联社 S-县（市）联合社、联社、合作社（县级） T-信用合作社 U-信用社、分社 V-储蓄所 X-其他分支机构 6.F-资金互助社 H-法人 7.J-金融资产管理公司 H-总公司 B-办事处 X-其他分支机构 8.K-信托公司 H-法人 9.N-汽车金融公司 H-法人 10.L-财务公司 H-总公司 B-分公司 X-其他分支机构 11.M-金融租赁公司 H-总公司 B-分公司 X-其他分支机构 12.P-货币经纪公司 H-总公司 B-分公司 X-其他分支机构 13.Q-贷款公司 H-总公司 B-分公司 X-其他分支机构 14.Z-其他类金融机构 Z类机构组织类别代码编码方法参照以上规则。 新增机构类型时，参照以上规则，根据实际情况定义其组织类别代码。 （四）第〔七〕位是发证机关代码，用数字表示。 1-银保监会 2-银监局 3-银监分局 （五）第〔八〕位至第〔十一〕是地址代码，用数字表示。按照《中华人民共和国行政区划代码》 （GB/T2260），取市（地区、自治州、盟）、直辖市行政区划代码前四位，作为地址代码。 地址代码示例如下：1100表示北京市，1200表示天津市，1301表示石家庄市，…… （六）第〔十二〕位至第〔十五〕位是顺序代码，用数字表示。机构类型代码、机构代码、组织类别代码、发证机关代码和地址代码相同的机构按照制发金融许可证的顺序编码。 三、机构编码的编制规则 编制机构编码时，按照从左至右的顺序依次确定机构类型代码、机构代码、组织类别代码、发证机关代码、地址代码、顺序代码，由计算机自动生成。 为了保证机构编码的唯一性，以利于电子计算机较长时间地存储数据，因行政许可变更需换发金融许可证，涉及机构编码变更的，原机构编码不再使用.金融机构终止的，机构编码不再使用。注销开业许可收回金融许可证的，机构编码不再使用。 | L10: =INDEX(数据元说明!A:F,MATCH(I10,数据元说明!C:C,0),6) -> C..30 | M10: 营业机构、管理机构必须填报“金融许可证号”，内设机构、虚拟机构及营业部取上一级管理机构的金融许可证号。 | N10: 修改 | O10: 备注
F11: 营业执照号 | G11: YYZZH | H11: 10104 | I11: 营业执照号 | J11: =INDEX(数据元说明!A:F,MATCH(I11,数据元说明!C:C,0),2) -> 002014 | K11: =INDEX(数据元说明!A:F,MATCH(I11,数据元说明!C:C,0),5) -> 已登记统一社会信用代码的，填18位统一社会信用代码；未登记统一社会信用代码的，按原有方式填写。 | L11: =INDEX(数据元说明!A:F,MATCH(I11,数据元说明!C:C,0),6) -> C..60 | M11: 营业机构、管理机构必须填报“营业执照号”，内设机构、虚拟机构及营业部取上一级管理机构的营业执照号 | N11: 修改 | O11: 备注
F12: 银行机构名称 | G12: YHJGMC | H12: 10105 | I12: 名称 | J12: =INDEX(数据元说明!A:F,MATCH(I12,数据元说明!C:C,0),2) -> 001001 | K12: =INDEX(数据元说明!A:F,MATCH(I12,数据元说明!C:C,0),5) -> 名称应与公章所使用的名称完全一致。银行机构以银保监会金融机构许可证登记名称为准。无独立金融机构许可证的机构，可在本名称中体现出机构特征。第三方支付平台填报第三方支付平台名称。 客户名称按照客户的不同类型按如下标准填报。 （1）集团客户，填报银行对该集团授信采用的集团客户名称。视同集团客户填报的供应链融资填报核心企业客户名称。 （2）单一法人客户，经有关部门批准正式使用的全称，与公章所使用的名称完全一致。视同单一法人客户填报的分公司，填报分公司全称，与分公司公章所使用的名称完全一致。客户是境内涉密机构的，客户名称填报为“*********”。 （3）同业客户，经有关部门批准正式使用的客户全称，与客户公章所使用的名称完全一致。 （4）自然人，与有效证件上的姓名一致。 （5）境外客户，客户名称应尽量以中文翻译填报，如没有可填报英文名称。 | L12: =INDEX(数据元说明!A:F,MATCH(I12,数据元说明!C:C,0),6) -> C..400 | M12: 需填写全称，有金融许可证号的需与金融许可证上的机构名称保持一致。例如：应填报“XX银行股份有限公司XX省分行”，不应填报为“XX省分行”。无独立金融机构许可证的机构，可在本名称中体现出机构特征。 | N12: 修改 | O12: 格式
F13: 机构类别 | G13: JGLB | H13: 10106 | I13: 机构类别 | J13: =INDEX(数据元说明!A:F,MATCH(I13,数据元说明!C:C,0),2) -> 001013 | K13: =INDEX(数据元说明!A:F,MATCH(I13,数据元说明!C:C,0),5) -> 管理机构，营业机构，虚拟机构，内设机构。 | L13: =INDEX(数据元说明!A:F,MATCH(I13,数据元说明!C:C,0),6) -> C..30 | M13: 仅允许填报为：管理机构，营业机构，虚拟机构，内设机构。 各行根据实际情况进行映射： 管理机构：总行、一级分行、专营机构； 营业机构：除总行、一级分行、专营机构以外的有金融许可证的实体机构。专营机构分支机构作为营业机构。营业部也作为营业机构，填报上一级管理机构的金融许可证号； 虚拟机构：指自助银行、ATM、网银、手机银行等渠道； 内设机构：如清算中心等内设部门。 | N13: 修改 | O13: 数据元说明、备注
F14: 行政区划代码 | G14: XZQHDM | H14: 10107 | I14: 地区代码 | J14: =INDEX(数据元说明!A:F,MATCH(I14,数据元说明!C:C,0),2) -> 001031 | K14: =INDEX(数据元说明!A:F,MATCH(I14,数据元说明!C:C,0),5) -> 境内地区参照《GB/T 2260-2020 中华人民共和国行政区划代码》填写国内行政区划代码，填写至二级分类，如110100。境外地区参照《GB/T 2659 世界各国和地区名称代码》定义的三字符代码，如USA。 | L14: =INDEX(数据元说明!A:F,MATCH(I14,数据元说明!C:C,0),6) -> C..6 | M14: 营业机构、管理机构必须填报实际的“行政区划代码”（要求到区县一级，6位代码），内设机构、虚拟机构，营业部取上一级管理机构的行政区划代码 | N14: 新增
F15: 营业状态 | G15: YYZT | H15: 10108 | I15: 营业状态 | J15: =INDEX(数据元说明!A:F,MATCH(I15,数据元说明!C:C,0),2) -> 001015 | K15: =INDEX(数据元说明!A:F,MATCH(I15,数据元说明!C:C,0),5) -> 营业，停业。 | L15: =INDEX(数据元说明!A:F,MATCH(I15,数据元说明!C:C,0),6) -> C6 | M15: 营业：正常、拟撤销等状态的机构 停业：歇业、筹建中等状态的机构
F16: 成立日期 | G16: CLRQ | H16: 10109 | I16: 日期 | J16: =INDEX(数据元说明!A:F,MATCH(I16,数据元说明!C:C,0),2) -> 001005 | K16: =INDEX(数据元说明!A:F,MATCH(I16,数据元说明!C:C,0),5) -> YYYYMMDD，默认值99991231。 | L16: =INDEX(数据元说明!A:F,MATCH(I16,数据元说明!C:C,0),6) -> C8 | N16: 修改 | O16: 数据项名称、数据项代码
F17: 机构地址 | G17: JGDZ | H17: 10110 | I17: 地址 | J17: =INDEX(数据元说明!A:F,MATCH(I17,数据元说明!C:C,0),2) -> 001008 | K17: =INDEX(数据元说明!A:F,MATCH(I17,数据元说明!C:C,0),5) -> 中文描述。个人填报个人住址。机构填报有关部门批准的有效证件上登记的地址。参照《企业法人营业执照》中的注册地填报，要写明省（区、市）、地（区、市、州、盟）、县（区、市、旗）。境外机构及境内涉密机构不填报。 | L17: =INDEX(数据元说明!A:F,MATCH(I17,数据元说明!C:C,0),6) -> C..400 | M17: 虚拟机构可为空
F18: 机构联系电话 | G18: JGLXDH | H18: 10111 | I18: 电话 | J18: =INDEX(数据元说明!A:F,MATCH(I18,数据元说明!C:C,0),2) -> 001009 | K18: =INDEX(数据元说明!A:F,MATCH(I18,数据元说明!C:C,0),5) -> 手机号码或者区号-固定电话号码。 | L18: =INDEX(数据元说明!A:F,MATCH(I18,数据元说明!C:C,0),6) -> C..30 | M18: 机构办公联系电话，区号-座机电话，虚拟机构、自助银行及自助设备机构、机构本部和仅承担内部核算职能的机构可为空。非隐私，不做变形。 | N18: 新增
F19: 负责人姓名 | G19: FZRXM | H19: 10112 | I19: 姓名 | J19: =INDEX(数据元说明!A:F,MATCH(I19,数据元说明!C:C,0),2) -> 001017 | K19: =INDEX(数据元说明!A:F,MATCH(I19,数据元说明!C:C,0),5) -> 姓名。 | L19: =INDEX(数据元说明!A:F,MATCH(I19,数据元说明!C:C,0),6) -> C..200 | M19: 非隐私，不做变形。虚拟机构、自助银行及自助设备机构、机构本部和仅承担内部核算职能的机构可为空。
F20: 负责人职务 | G20: FZRZW | H20: 10113 | I20: 职务 | J20: =INDEX(数据元说明!A:F,MATCH(I20,数据元说明!C:C,0),2) -> 001019 | K20: =INDEX(数据元说明!A:F,MATCH(I20,数据元说明!C:C,0),5) -> 中文字典或中文描述，银行自定义。 | L20: =INDEX(数据元说明!A:F,MATCH(I20,数据元说明!C:C,0),6) -> C..200 | M20: 虚拟机构、自助银行及自助设备机构、机构本部和仅承担内部核算职能的机构可为空。
F21: 负责人联系电话 | G21: FZRLXDH | H21: 10114 | I21: 电话 | J21: =INDEX(数据元说明!A:F,MATCH(I21,数据元说明!C:C,0),2) -> 001009 | K21: =INDEX(数据元说明!A:F,MATCH(I21,数据元说明!C:C,0),5) -> 手机号码或者区号-固定电话号码。 | L21: =INDEX(数据元说明!A:F,MATCH(I21,数据元说明!C:C,0),6) -> C..30 | M21: 负责人联系电话，区号-座机电话/手机，虚拟机构、自助银行及自助设备机构、机构本部和仅承担内部核算职能的机构可为空。非隐私，不做变形 | N21: 修改 | O21: 备注
F22: 备注 | G22: BBZ | H22: 10115 | I22: 备注 | J22: =INDEX(数据元说明!A:F,MATCH(I22,数据元说明!C:C,0),2) -> 001040 | K22: =INDEX(数据元说明!A:F,MATCH(I22,数据元说明!C:C,0),5) -> 银行自定义。 | L22: =INDEX(数据元说明!A:F,MATCH(I22,数据元说明!C:C,0),6) -> C..600 | M22: 描述其他字段未能详尽说明的情况，如是否是历史数据、未通过校验原因等可在备注栏说明，简述即可，不必详述，不同备注事项用分号或句号分隔开。 | N22: 新增
F23: 采集日期 | G23: CJRQ | H23: 10116 | I23: 日期 | J23: =INDEX(数据元说明!A:F,MATCH(I23,数据元说明!C:C,0),2) -> 001005 | K23: =INDEX(数据元说明!A:F,MATCH(I23,数据元说明!C:C,0),5) -> YYYYMMDD，默认值99991231。 | L23: =INDEX(数据元说明!A:F,MATCH(I23,数据元说明!C:C,0),6) -> C8 | M23: PK。采集日期指该期（批次）数据报送的期末日期，例如：按日采集的表，采集日期应为每日；按月采集的表，采集日期应为月末最后一天；以此类推。有特殊报送要求的，应以报送要求的截至日期为采集日期。
C24: YGB | D24: 员工表 | E24: 102 | M24: =INDEX(表结构总览!E:H,MATCH(D24,表结构总览!E:E,0),4) -> 在职类正式/非正式员工需每月报送，非正式员工包括合同制、劳务派遣员工。员工状态转为离职、退休、开除、死亡、调出等的，在报送该员工最后状态的次月可不再报送。子公司员工不用报送，调动至子公司的员工按离职报送。董事、监事不用报送。 | N24: 修改 | O24: 备注
F25: 银行机构代码 | G25: YHJGDM | H25: 10201 | I25: 银行机构代码 | J25: =INDEX(数据元说明!A:F,MATCH(I25,数据元说明!C:C,0),2) -> 001010 | K25: =INDEX(数据元说明!A:F,MATCH(I25,数据元说明!C:C,0),5) -> 12位人行支付行号或SWIFT行号。 | L25: =INDEX(数据元说明!A:F,MATCH(I25,数据元说明!C:C,0),6) -> C..30 | M25: 关联数据项：机构信息表.银行机构代码
F26: 金融许可证号 | G26: JRXKZH | H26: 10202 | I26: 金融许可证号 | J26: =INDEX(数据元说明!A:F,MATCH(I26,数据元说明!C:C,0),2) -> 001011 | K26: =INDEX(数据元说明!A:F,MATCH(I26,数据元说明!C:C,0),5) -> 金融许可证机构编码编制规则（试行） 一、机构编码结构 机构编码由大写英文字母和数字组成，共15位。分六个部分，分别是机构类型代码、机构代码、组织类别代码、发证机关代码、地址代码、顺序代码，从左至右顺序排列，如下表所示。 二、机构编码含义 （一）第［一］位是机构类型代码，用大写英文字母表示。 A-政策性银行 B-商业银行 C-农村合作银行 D-城市信用社 E-农村信用社 F-资金互助社 J-金融资产管理公司 K-信托公司 L-财务公司 M-金融租赁公司 N-汽车金融公司 P-货币经纪公司 Q-贷款公司 Z-其他类金融机构 新增机构类型时，根据需要确定机构类型代码。 （二）第［二］位至第［五］位是机构代码，用数字表示。 1.每个法人机构指定唯一的代码，由计算机系统按照规则自动生成。除农村信用社、资金互助社、贷款公司（E、F、Q类机构）外，全国统一编码。E、F、Q类机构在省（自治区、直辖市）范围内统一编码。 2.新设立的机构依照所属机构类型顺序排列。 机构代码编码示例如下： A-政策性银行 0001-国家开发银行 …… B-商业银行 0001-中国工商银行股份有限公司 …… C-农村合作银行 0001-天津大港农村合作银行 …… D-城市信用社 0001-邯郸市城市信用社股份有限公司 …… E-农村信用社天津市 0001-天津市宝坻区农村信用合作联社 …… 新疆维吾尔自治区 0001-新疆维吾尔自治区农村信用社联合社 …… F-资金互助社 吉林省 0001-吉林省梨树县闰家村百信农村资金互助社 …… 青海省 0001-青海省乐都县雨润镇兴乐农村资金互助社 …… J-金融资产管理公司 0001-中国华融资产管理公司 …… K-信托投资公司 0001-中诚信托投资有限责任公司 …… L-财务公司 0001-中海石油财务有限责任公司 …… M-金融租赁公司 0001-中国外贸金融租赁公司 …… N-汽车金融公司 0001-大众汽车金融（中国）有限公司 …… P-货币经纪公司 0001-上海国利货币经纪有限公司 …… Q-贷款公司四川省 0001-四川省仪陇县惠民贷款有限责任公司 …… 新疆维吾尔自治区 0001- …… Z-其他类金融机构 0001-中央国债登记结算有限责任公司 …… （三）第〔六〕位是组织类别代码，用大写英文字母表示。 机构类型不同，组织类别代码的含义不同。定义如下： 1.A-政策性银行 H-总行 G-总行营业部 H-级分行 K-一级分行营业部 M-二级分行 S-支行 X-其他分支机构 2.B-商业银行 H-总行 G-总行营业部、专营机构 B-一级分行 K-一级分行营业部 L-二级分行 M-直属支行 N-二级分行营业部 S-支行 U-分理处、办事处、营业所 V-储蓄所 X-其他分支机构 3.C-农村合作银行 H-总行 S-支行 U-分理处 V-储蓄所 X-其他分支机构 4.D-城市信用社 H-法人 S-分社、营业部 X-其他分支机构 5.E-农村信用社 H-省（自治区、直辖市）联合社 B-地（市）联合社、联社 S-县（市）联合社、联社、合作社（县级） T-信用合作社 U-信用社、分社 V-储蓄所 X-其他分支机构 6.F-资金互助社 H-法人 7.J-金融资产管理公司 H-总公司 B-办事处 X-其他分支机构 8.K-信托公司 H-法人 9.N-汽车金融公司 H-法人 10.L-财务公司 H-总公司 B-分公司 X-其他分支机构 11.M-金融租赁公司 H-总公司 B-分公司 X-其他分支机构 12.P-货币经纪公司 H-总公司 B-分公司 X-其他分支机构 13.Q-贷款公司 H-总公司 B-分公司 X-其他分支机构 14.Z-其他类金融机构 Z类机构组织类别代码编码方法参照以上规则。 新增机构类型时，参照以上规则，根据实际情况定义其组织类别代码。 （四）第〔七〕位是发证机关代码，用数字表示。 1-银保监会 2-银监局 3-银监分局 （五）第〔八〕位至第〔十一〕是地址代码，用数字表示。按照《中华人民共和国行政区划代码》 （GB/T2260），取市（地区、自治州、盟）、直辖市行政区划代码前四位，作为地址代码。 地址代码示例如下：1100表示北京市，1200表示天津市，1301表示石家庄市，…… （六）第〔十二〕位至第〔十五〕位是顺序代码，用数字表示。机构类型代码、机构代码、组织类别代码、发证机关代码和地址代码相同的机构按照制发金融许可证的顺序编码。 三、机构编码的编制规则 编制机构编码时，按照从左至右的顺序依次确定机构类型代码、机构代码、组织类别代码、发证机关代码、地址代码、顺序代码，由计算机自动生成。 为了保证机构编码的唯一性，以利于电子计算机较长时间地存储数据，因行政许可变更需换发金融许可证，涉及机构编码变更的，原机构编码不再使用.金融机构终止的，机构编码不再使用。注销开业许可收回金融许可证的，机构编码不再使用。 | L26: =INDEX(数据元说明!A:F,MATCH(I26,数据元说明!C:C,0),6) -> C..30 | M26: 营业机构、管理机构必须填报“金融许可证号”，内设机构、虚拟机构及营业部取上一级管理机构的金融许可证号。 | N26: 修改 | O26: 备注
F27: 内部机构号 | G27: NBJGH | H27: 10203 | I27: 内部机构号 | J27: =INDEX(数据元说明!A:F,MATCH(I27,数据元说明!C:C,0),2) -> 001012 | K27: =INDEX(数据元说明!A:F,MATCH(I27,数据元说明!C:C,0),5) -> 银行内部机构号。应具有标识机构的唯一性。 | L27: =INDEX(数据元说明!A:F,MATCH(I27,数据元说明!C:C,0),6) -> C..30 | M27: 关联数据项：机构信息表.内部机构号。员工如果采集区间发生过更换机构，按采集时点的最后填报内部机构号。 | N27: 修改 | O27: 备注
F28: 银行机构名称 | G28: YHJGMC | H28: 10204 | I28: 名称 | J28: =INDEX(数据元说明!A:F,MATCH(I28,数据元说明!C:C,0),2) -> 001001 | K28: =INDEX(数据元说明!A:F,MATCH(I28,数据元说明!C:C,0),5) -> 名称应与公章所使用的名称完全一致。银行机构以银保监会金融机构许可证登记名称为准。无独立金融机构许可证的机构，可在本名称中体现出机构特征。第三方支付平台填报第三方支付平台名称。 客户名称按照客户的不同类型按如下标准填报。 （1）集团客户，填报银行对该集团授信采用的集团客户名称。视同集团客户填报的供应链融资填报核心企业客户名称。 （2）单一法人客户，经有关部门批准正式使用的全称，与公章所使用的名称完全一致。视同单一法人客户填报的分公司，填报分公司全称，与分公司公章所使用的名称完全一致。客户是境内涉密机构的，客户名称填报为“*********”。 （3）同业客户，经有关部门批准正式使用的客户全称，与客户公章所使用的名称完全一致。 （4）自然人，与有效证件上的姓名一致。 （5）境外客户，客户名称应尽量以中文翻译填报，如没有可填报英文名称。 | L28: =INDEX(数据元说明!A:F,MATCH(I28,数据元说明!C:C,0),6) -> C..400 | M28: 需填写全称，有金融许可证号的需与金融许可证上的机构名称保持一致。关联数据项：机构信息表.银行机构名称 | N28: 修改 | O28: 格式
F29: 工号 | G29: GH | H29: 10205 | I29: 工号 | J29: =INDEX(数据元说明!A:F,MATCH(I29,数据元说明!C:C,0),2) -> 001016 | K29: =INDEX(数据元说明!A:F,MATCH(I29,数据元说明!C:C,0),5) -> 工号，银行自定义。 | L29: =INDEX(数据元说明!A:F,MATCH(I29,数据元说明!C:C,0),6) -> C..30 | M29: PK。 | N29: 修改 | P29: 调整数据项位置
F30: 姓名 | G30: XM | H30: 10206 | I30: 姓名 | J30: =INDEX(数据元说明!A:F,MATCH(I30,数据元说明!C:C,0),2) -> 001017 | K30: =INDEX(数据元说明!A:F,MATCH(I30,数据元说明!C:C,0),5) -> 姓名。 | L30: =INDEX(数据元说明!A:F,MATCH(I30,数据元说明!C:C,0),6) -> C..200 | M30: 员工姓名为非隐私，不做变形。 | N30: 修改 | O30: 备注
F31: 证件类别 | G31: ZJLB | H31: 10207 | I31: 证件类别 | J31: =INDEX(数据元说明!A:F,MATCH(I31,数据元说明!C:C,0),2) -> 002002 | K31: =INDEX(数据元说明!A:F,MATCH(I31,数据元说明!C:C,0),5) -> 同业客户：银行机构代码，金融许可证号，SWIFT编码，其他-XX。 对公客户：统一社会信用代码，组织机构代码，营业执照（工商注册号），公司注册证书，全球法人识别码，其他-XX。 个人客户：居民身份证，军官证，文职干部证，警官证，士兵证，户口簿，临时身份证，其他有效通行旅行证件，护照，学生证，无证件，其他-XX。 无法以枚举类型填报的，以“其他-XX”报送，其中“XX”为银行自定义类型。 对公客户优先填报统一社会信用代码，没有统一社会信用代码的对公客户填报组织机构代码。组织机构代码、统一社会信用代码均没有的可以填报客户提供的批文文号、开户主证件、上级机构统一社会信用代码等，以“其他-XX”填报。 | L31: =INDEX(数据元说明!A:F,MATCH(I31,数据元说明!C:C,0),6) -> C..60
F32: 证件号码 | G32: ZJHM | H32: 10208 | I32: 证件号码 | J32: =INDEX(数据元说明!A:F,MATCH(I32,数据元说明!C:C,0),2) -> 002003 | K32: =INDEX(数据元说明!A:F,MATCH(I32,数据元说明!C:C,0),5) -> 与证件类别对应的证件号码。涉及个人身份证件时需按照本规范给定规则进行脱敏处理。 | L32: =INDEX(数据元说明!A:F,MATCH(I32,数据元说明!C:C,0),6) -> C..70 | M32: 隐私，银行机构变形。变形规则见《采集技术接口说明》。 | N32: 修改 | O32: 数据项代码 | P32: 调整数据项位置
F33: 联系电话 | G33: LXDH | H33: 10209 | I33: 电话 | J33: =INDEX(数据元说明!A:F,MATCH(I33,数据元说明!C:C,0),2) -> 001009 | K33: =INDEX(数据元说明!A:F,MATCH(I33,数据元说明!C:C,0),5) -> 手机号码或者区号-固定电话号码。 | L33: =INDEX(数据元说明!A:F,MATCH(I33,数据元说明!C:C,0),6) -> C..30 | M33: 非隐私，不做变形。 | N33: 修改 | O33: 备注
F34: 所属部门 | G34: SSBM | H34: 10210 | I34: 所属部门 | J34: =INDEX(数据元说明!A:F,MATCH(I34,数据元说明!C:C,0),2) -> 001018 | K34: =INDEX(数据元说明!A:F,MATCH(I34,数据元说明!C:C,0),5) -> 中文字典或中文描述，银行自定义。 | L34: =INDEX(数据元说明!A:F,MATCH(I34,数据元说明!C:C,0),6) -> C..200
F35: 岗位编号 | G35: GWBH | H35: 10211 | I35: 岗位编号 | J35: =INDEX(数据元说明!A:F,MATCH(I35,数据元说明!C:C,0),2) -> 001025 | K35: =INDEX(数据元说明!A:F,MATCH(I35,数据元说明!C:C,0),5) -> 银行自定义。 | L35: =INDEX(数据元说明!A:F,MATCH(I35,数据元说明!C:C,0),6) -> C..60 | M35: PK。存在多个岗位时，按照多条报送。关联数据项：岗位信息表.岗位编号。 | N35: 修改 | O35: 备注 | P35: 增加备注说明
F36: 岗位名称 | G36: GWMC | H36: 10212 | I36: 岗位名称 | J36: =INDEX(数据元说明!A:F,MATCH(I36,数据元说明!C:C,0),2) -> 001027 | K36: =INDEX(数据元说明!A:F,MATCH(I36,数据元说明!C:C,0),5) -> 岗位名称，中文字典或中文描述，银行自定义。 | L36: =INDEX(数据元说明!A:F,MATCH(I36,数据元说明!C:C,0),6) -> C..200 | M36: 存在多个岗位时，按照多条报送。关联数据项：岗位信息表.岗位名称 | N36: 新增
F37: 员工状态 | G37: YGZT | H37: 10213 | I37: 员工状态 | J37: =INDEX(数据元说明!A:F,MATCH(I37,数据元说明!C:C,0),2) -> 001037 | K37: =INDEX(数据元说明!A:F,MATCH(I37,数据元说明!C:C,0),5) -> 正式员工离职，正式员工在职，非正式员工离职，非正式员工在职，内退，退休，开除，死亡，调出，其他-银行自定义。无法以枚举类型填报的，以“其他-XX”填报，其中“XX”为银行自定义类型。 | L37: =INDEX(数据元说明!A:F,MATCH(I37,数据元说明!C:C,0),6) -> C..30 | M37: 正式员工停职属于正式员工在职,借调、挂职、病休等均属于正式员工在职类,非正式员工停职属于非正式员工在职,开除包括劝退、辞退等员工非主动离职，调出指本行系统内调动，如从北京分行调至总行。 | N37: 修改 | O37: 数据元、备注 | P37: 增加备注说明
F38: 备注 | G38: BBZ | H38: 10214 | I38: 备注 | J38: =INDEX(数据元说明!A:F,MATCH(I38,数据元说明!C:C,0),2) -> 001040 | K38: =INDEX(数据元说明!A:F,MATCH(I38,数据元说明!C:C,0),5) -> 银行自定义。 | L38: =INDEX(数据元说明!A:F,MATCH(I38,数据元说明!C:C,0),6) -> C..600 | M38: 描述其他字段未能详尽说明的情况，如是否是历史数据、未通过校验原因等可在备注栏说明，简述即可，不必详述，不同备注事项用分号或句号分隔开。 | N38: 新增
F39: 采集日期 | G39: CJRQ | H39: 10215 | I39: 日期 | J39: =INDEX(数据元说明!A:F,MATCH(I39,数据元说明!C:C,0),2) -> 001005 | K39: =INDEX(数据元说明!A:F,MATCH(I39,数据元说明!C:C,0),5) -> YYYYMMDD，默认值99991231。 | L39: =INDEX(数据元说明!A:F,MATCH(I39,数据元说明!C:C,0),6) -> C8 | M39: PK。采集日期指该期（批次）数据报送的期末日期，例如：按日采集的表，采集日期应为每日；按月采集的表，采集日期应为月末最后一天；以此类推。有特殊报送要求的，应以报送要求的截至日期为采集日期。
C40: GYB | D40: 柜员表 | E40: 103 | M40: =INDEX(表结构总览!E:H,MATCH(D40,表结构总览!E:E,0),4) -> 包含实体柜员和虚拟柜员。为虚拟柜员时，工号、银行机构代码等字段依业务实际填列或留为缺失值，如报送虚拟柜员，则通过“柜员类型”字段进行区分；柜员状态转为注销、无效等时，可在报送该条数据最终状态的次月不再报送。 | N40: 修改 | O40: 备注 | P40: 增加备注说明
F41: 银行机构代码 | G41: YHJGDM | H41: 10301 | I41: 银行机构代码 | J41: =INDEX(数据元说明!A:F,MATCH(I41,数据元说明!C:C,0),2) -> 001010 | K41: =INDEX(数据元说明!A:F,MATCH(I41,数据元说明!C:C,0),5) -> 12位人行支付行号或SWIFT行号。 | L41: =INDEX(数据元说明!A:F,MATCH(I41,数据元说明!C:C,0),6) -> C..30 | M41: 关联数据项：机构信息表.银行机构代码
F42: 金融许可证号 | G42: JRXKZH | H42: 10302 | I42: 金融许可证号 | J42: =INDEX(数据元说明!A:F,MATCH(I42,数据元说明!C:C,0),2) -> 001011 | K42: =INDEX(数据元说明!A:F,MATCH(I42,数据元说明!C:C,0),5) -> 金融许可证机构编码编制规则（试行） 一、机构编码结构 机构编码由大写英文字母和数字组成，共15位。分六个部分，分别是机构类型代码、机构代码、组织类别代码、发证机关代码、地址代码、顺序代码，从左至右顺序排列，如下表所示。 二、机构编码含义 （一）第［一］位是机构类型代码，用大写英文字母表示。 A-政策性银行 B-商业银行 C-农村合作银行 D-城市信用社 E-农村信用社 F-资金互助社 J-金融资产管理公司 K-信托公司 L-财务公司 M-金融租赁公司 N-汽车金融公司 P-货币经纪公司 Q-贷款公司 Z-其他类金融机构 新增机构类型时，根据需要确定机构类型代码。 （二）第［二］位至第［五］位是机构代码，用数字表示。 1.每个法人机构指定唯一的代码，由计算机系统按照规则自动生成。除农村信用社、资金互助社、贷款公司（E、F、Q类机构）外，全国统一编码。E、F、Q类机构在省（自治区、直辖市）范围内统一编码。 2.新设立的机构依照所属机构类型顺序排列。 机构代码编码示例如下： A-政策性银行 0001-国家开发银行 …… B-商业银行 0001-中国工商银行股份有限公司 …… C-农村合作银行 0001-天津大港农村合作银行 …… D-城市信用社 0001-邯郸市城市信用社股份有限公司 …… E-农村信用社天津市 0001-天津市宝坻区农村信用合作联社 …… 新疆维吾尔自治区 0001-新疆维吾尔自治区农村信用社联合社 …… F-资金互助社 吉林省 0001-吉林省梨树县闰家村百信农村资金互助社 …… 青海省 0001-青海省乐都县雨润镇兴乐农村资金互助社 …… J-金融资产管理公司 0001-中国华融资产管理公司 …… K-信托投资公司 0001-中诚信托投资有限责任公司 …… L-财务公司 0001-中海石油财务有限责任公司 …… M-金融租赁公司 0001-中国外贸金融租赁公司 …… N-汽车金融公司 0001-大众汽车金融（中国）有限公司 …… P-货币经纪公司 0001-上海国利货币经纪有限公司 …… Q-贷款公司四川省 0001-四川省仪陇县惠民贷款有限责任公司 …… 新疆维吾尔自治区 0001- …… Z-其他类金融机构 0001-中央国债登记结算有限责任公司 …… （三）第〔六〕位是组织类别代码，用大写英文字母表示。 机构类型不同，组织类别代码的含义不同。定义如下： 1.A-政策性银行 H-总行 G-总行营业部 H-级分行 K-一级分行营业部 M-二级分行 S-支行 X-其他分支机构 2.B-商业银行 H-总行 G-总行营业部、专营机构 B-一级分行 K-一级分行营业部 L-二级分行 M-直属支行 N-二级分行营业部 S-支行 U-分理处、办事处、营业所 V-储蓄所 X-其他分支机构 3.C-农村合作银行 H-总行 S-支行 U-分理处 V-储蓄所 X-其他分支机构 4.D-城市信用社 H-法人 S-分社、营业部 X-其他分支机构 5.E-农村信用社 H-省（自治区、直辖市）联合社 B-地（市）联合社、联社 S-县（市）联合社、联社、合作社（县级） T-信用合作社 U-信用社、分社 V-储蓄所 X-其他分支机构 6.F-资金互助社 H-法人 7.J-金融资产管理公司 H-总公司 B-办事处 X-其他分支机构 8.K-信托公司 H-法人 9.N-汽车金融公司 H-法人 10.L-财务公司 H-总公司 B-分公司 X-其他分支机构 11.M-金融租赁公司 H-总公司 B-分公司 X-其他分支机构 12.P-货币经纪公司 H-总公司 B-分公司 X-其他分支机构 13.Q-贷款公司 H-总公司 B-分公司 X-其他分支机构 14.Z-其他类金融机构 Z类机构组织类别代码编码方法参照以上规则。 新增机构类型时，参照以上规则，根据实际情况定义其组织类别代码。 （四）第〔七〕位是发证机关代码，用数字表示。 1-银保监会 2-银监局 3-银监分局 （五）第〔八〕位至第〔十一〕是地址代码，用数字表示。按照《中华人民共和国行政区划代码》 （GB/T2260），取市（地区、自治州、盟）、直辖市行政区划代码前四位，作为地址代码。 地址代码示例如下：1100表示北京市，1200表示天津市，1301表示石家庄市，…… （六）第〔十二〕位至第〔十五〕位是顺序代码，用数字表示。机构类型代码、机构代码、组织类别代码、发证机关代码和地址代码相同的机构按照制发金融许可证的顺序编码。 三、机构编码的编制规则 编制机构编码时，按照从左至右的顺序依次确定机构类型代码、机构代码、组织类别代码、发证机关代码、地址代码、顺序代码，由计算机自动生成。 为了保证机构编码的唯一性，以利于电子计算机较长时间地存储数据，因行政许可变更需换发金融许可证，涉及机构编码变更的，原机构编码不再使用.金融机构终止的，机构编码不再使用。注销开业许可收回金融许可证的，机构编码不再使用。 | L42: =INDEX(数据元说明!A:F,MATCH(I42,数据元说明!C:C,0),6) -> C..30 | M42: 营业机构、管理机构必须填报“金融许可证号”，内设机构、虚拟机构及营业部取上一级管理机构的金融许可证号。 | N42: 修改 | O42: 备注
F43: 内部机构号 | G43: NBJGH | H43: 10303 | I43: 内部机构号 | J43: =INDEX(数据元说明!A:F,MATCH(I43,数据元说明!C:C,0),2) -> 001012 | K43: =INDEX(数据元说明!A:F,MATCH(I43,数据元说明!C:C,0),5) -> 银行内部机构号。应具有标识机构的唯一性。 | L43: =INDEX(数据元说明!A:F,MATCH(I43,数据元说明!C:C,0),6) -> C..30 | M43: PK。关联数据项：机构信息表.内部机构号
...

Sheet 自营报送范围
A1: 自营资金业务报送范围
A3: 业务大类 | B3: 业务中类 | C3: 业务小类
A4: 同业往来 | B4: 买入返售 | C4: 买入返售证券
C5: 买入返售债权
C6: 买入返售信贷资产
C7: 其他-银行自定义
B8: 卖出回购 | C8: 卖出回购证券
C9: 卖出回购债权
C10: 卖出回购信贷资产
C11: 其他-银行自定义
B12: 拆入 | C12: 拆入银行金融机构
C13: 拆入非银行金融机构
B14: 拆出 | C14: 拆出银行金融机构
C15: 拆出非银行金融机构
B16: 同业借款 | C16: 境内同业借款
C17: 境外同业借款
B18: 同业代付 | C18: 代理境内同业付款
C19: 代理境外同业付款
B20: 存放同业 | C20: 非结算性存放同业
C21: 结算性存放同业
B22: 同业存单 | C22: 同业存单发行
C23: 同业存单投资
B24: 债券发行 | C24: 商业银行债
C25: 银行次级债
C26: 银行永续债
C27: 其他-银行自定义
B28: 其他 | C28: 债券借贷
C29: 银行自定义
A30: 债券投资与同业投资 | B30: 债券投资 | C30: 国债
C31: 地方政府债
C32: 央票
C33: 政府支持机构债
C34: 政策性金融债
C35: 商业性金融债
C36: 非金融企业债券
C37: 资产支持证券（信贷资产证券化）
C38: 资产支持证券（交易所资产支持证券）
C39: 资产支持证券（资产支持票据）
C40: 外国债券
C41: 其他-银行自定义
...

Sheet 删除的表和数据项
A1: 数据表和数据项删除情况一览表
A3: 传输文件名称 | B3: 表名 | C3: 数据项名称 | D3: 数据项代码 | E3: 数据元 | F3: 数据元编码 | G3: 数据元说明 | H3: 格式 | I3: 变更类型 | J3: 变更原因
B5: 所有明细记录表（9张）
C6: 核心交易流水号、子交易流水号、笔次序号 | I6: 删除数据项 | J6: 不同银行机构的核心系统定义不同，无法与这三个数据项完全对应。使用“时间戳”数据项（19位）（如：时间戳(纳秒)：1530027865231834600），来标识交易序列，代替“流水号”。
C7: 开户行机构号 | D7: KHHJGH | E7: 内部机构号 | F7: 001011 | G7: 银行内部机构号。应具有标识机构的唯一性。 | H7: C..30 | I7: 删除数据项 | J7: 与“内部机构号”重复
B8: 信贷合同表、信贷借据表、贷款展期
C9: 基准利率 | D9: JZLL | E9: 基准利率 | F9: 010030 | G9: 百分比为单位，即1/100，一般为年利。 | H9: D10.6 | I9: 删除数据项 | J9: 现在统一用“实际利率”来表示
C10: 利率浮动 | D10: LLFD | E10: 利率浮动 | F10: 005003 | G10: 基准点为单位。浮动比例与上浮比例均折算点数填报。如上浮1%是填100.00，下浮1%是填-100.00，精确到小数点后2位。如果利率类型是固定利率，则利率浮动填写0.00。如利率类型是浮动利率，则与利率基准结合进行计算。 | H10: D8.5 | I10: 删除数据项 | J10: 现在统一用“实际利率”来表示
C11: 是否LPR | D11: SFLPR | E11: 是否标志 | F11: 001002 | G11: 是，否。 | H11: C..4 | I11: 删除数据项 | J11: “利率类型”修改为：LPR，非LPR
A12: JGXXB | B12: 机构信息表
C13: 机构工作开始时间 | D13: JGGZKSSJ | E13: 时间 | F13: 001007 | G13: 24小时制时间，精确到秒。hhmmss，默认值000000。 | H13: C20 | I13: 删除数据项 | J13: 非监管关注重点
C14: 机构工作终止时间 | D14: JGGZZZSJ | E14: 时间 | F14: 001007 | G14: 24小时制时间，精确到秒。hhmmss，默认值000000。 | H14: C20 | I14: 删除数据项 | J14: 非监管关注重点
C15: 邮政编码 | D15: YZBM | E15: 邮政编码 | F15: 001013 | G15: 该机构注册地邮政编码，6位。超过6位的只取前6位。 | H15: C6 | I15: 删除数据项 | J15: 新增了行政区划代码数据项
C16: 网点号 | D16: WDH | E16: 网点号 | F16: 001014 | G16: 银行内部机构号。 | H16: C..30 | I16: 删除数据项 | J16: 已有内部机构号
A17: YGB | B17: 员工表
C18: 职务 | D18: ZW | E18: 职务 | F18: 001019 | G18: 中文字典或中文描述，银行自定义。 | H18: C..60 | I18: 删除数据项 | J18: 已有岗位编号和岗位名称
C19: 网点号 | D19: WDH | E19: 网点号 | F19: 001014 | G19: 银行内部机构号。 | H19: C..30 | I19: 删除数据项 | J19: 已有内部机构号
A20: GDXX | B20: 股东信息
C21: 实控人姓名 | D21: SKRXM | E21: 姓名 | F21: 001016 | G21: 姓名。 | H21: C..100 | I21: 删除数据项 | J21: 银行自身实控人，无需每条都报送。
C22: 实控人证件类别 | D22: SKRZJLB | E22: 证件类别 | F22: 002002 | G22: 对公客户：统一社会信用代码，组织机构代码 个人客户：居民身份证，军官证，文职干部证，警官证，士兵证，户口簿，临时身份证，其他有效通行旅行证件，护照，学生证，无证件，其他-银行自定义。无法以枚举类型填报的，以“其它-XX”填报，其中“XX”为银行自定义类型。 | H22: C..60 | I22: 删除数据项 | J22: 银行自身实控人，无需每条都报送。
C23: 实控人证件号码 | D23: SKRZJHM | E23: 证件号码 | F23: 002003 | G23: 证件号码。涉及个人身份证件时需按照本规范给定规则进行脱敏处理。 | H23: C..70 | I23: 删除数据项 | J23: 银行自身实控人，无需每条都报送。
A24: GRJCXX | B24: 个人基础信息
C25: 客户英文姓名 | D25: KHYWXM | E25: 客户英文姓名 | F25: 002002 | G25: 英文或拼音。 | H25: C..200 | I25: 删除数据项 | J25: 非监管关注重点
C26: 配偶对应客户号 | D26: PODYKHH | E26: 客户统一编号 | F26: 002001 | G26: 银行自定义的唯一识别客户的标识。供应链融资的填写供应链融资编码。 | H26: C..60 | I26: 删除数据项 | J26: 非监管关注重点
C27: 来源系统 | D27: LYXT | E27: 来源系统 | F27: 002005 | G27: 该客户信息源自的系统名称。 | H27: C..100 | I27: 删除数据项 | J27: 非监管关注重点
C28: 家庭住址 | D28: JTZZ | E28: 地址 | F28: 001007 | G28: 中文描述。个人住址。金融机构以金融机构许可证登记地址为准。集团母公司为境内企业的，按照《企业法人营业执照》中的注册地填报，要写明省（区、市）、地（区、市、州、盟）、县（区、市、旗）。集团母公司为境外企业的，不填报。 | H28: C..400 | I28: 删除数据项 | J28: 非监管关注重点
C29: 家庭电话 | D29: JTDH | E29: 电话 | F29: 001010 | G29: 银行自定义。 | H29: C..30 | I29: 删除数据项 | J29: 统一新增了“联系电话”字段
C30: 移动电话 | D30: YDDH | E30: 电话 | F30: 001010 | G30: 银行自定义。 | H30: C..30 | I30: 删除数据项 | J30: 统一新增了“联系电话”字段
C31: 家庭月收入 | D31: JTYSR | E31: 金额 | F31: 003011 | G31: 与币种相对应金额。 | H31: D20.2 | I31: 删除数据项 | J31: 较多银行未采集
C32: 配偶姓名 | D32: POXM | E32: 姓名 | F32: 001016 | G32: 姓名。 | H32: C..200 | I32: 删除数据项 | J32: 配偶信息可在“个人客户关系表”中查询
C33: 配偶联系电话 | D33: POLXDH | E33: 电话 | F33: 001008 | G33: 手机号码或者区号-固定电话号码。 | H33: C..30 | I33: 删除数据项 | J33: 配偶信息可在“个人客户关系表”中查询
C34: 配偶移动电话 | D34: POYDDH | E34: 电话 | F34: 001008 | G34: 手机号码或者区号-固定电话号码。 | H34: C..30 | I34: 删除数据项 | J34: 配偶信息可在“个人客户关系表”中查询
C35: 配偶证件类别 | D35: POZJLB | E35: 证件类别 | F35: 002002 | G35: 对公客户：统一社会信用代码，没有统一社会信用代码的对公客户填报组织机构代码。 个人客户：居民身份证，军官证，文职干部证，警官证，士兵证，户口簿，临时身份证，其他有效通行旅行证件，护照，学生证，无证件，其他-XX。无法以枚举类型填报的，以“XX”报送，其中“XX”为银行自定义类型。 | H35: C..60 | I35: 删除数据项 | J35: 配偶信息可在“个人客户关系表”中查询
C36: 上黑名单原因 | D36: SHMDYY | E36: 上黑名单原因 | F36: 002010 | G36: 中文字典或中文描述，银行自定义。 | H36: C..400 | I36: 删除数据项 | J36: 非监管关注重点
A37: GRKHGXXX | B37: 个人客户关系信息 | C37: 配偶证件号码 | D37: POZJHM | E37: 证件号码 | F37: 002003 | G37: 证件号码。涉及个人身份证件时需按照本规范给定规则进行脱敏处理。 | H37: C..70
C38: 对应个人客户工作单位名称 | D38: DYGRKHGZDWMC | E38: 名称 | F38: 001001 | G38: 名称应与公章所使用的名称完全一致。银行机构以银保监会金融机构许可证登记名称为准。无独立金融机构许可证的机构，可在本名称中体现出机构特征。 客户名称按照客户的不同类型按如下标准填报。 （1）集团客户，填报银行对该集团授信采用的集团客户名称。视同集团客户填报的供应链融资填报核心企业客户名称。 （2）单一法人客户，经有关部门批准正式使用的全称，与公章所使用的名称完全一致。视同单一法人客户填报的分公司，填报分公司全称，与分公司公章所使用的名称完全一致。 （3）同业客户，经有关部门批准正式使用的客户全称，与客户公章所使用的名称完全一致。 （4）客户是境外法人的，客户名称填报规范的中文翻译；客户是境内涉密法人的，客户名称填报为“*********”。 （5）自然人，与有效证件上的姓名一致。 | H38: C..400 | I38: 删除数据项 | J38: 个人基础信息已有该数据
C39: 对应个人客户工作单位地址 | D39: DYGRKHGZDWDZ | E39: 地址 | F39: 001007 | G39: 中文描述。个人住址。金融机构以金融机构许可证登记地址为准。集团母公司为境内企业的，按照《企业法人营业执照》中的注册地填报，要写明省（区、市）、地（区、市、州、盟）、县（区、市、旗）。集团母公司为境外企业的，不填报。 | H39: C..400 | I39: 删除数据项 | J39: 个人基础信息已有该数据
C40: 对应个人客户工作单位电话 | D40: DYGRKHGZDWDH | E40: 电话 | F40: 001008 | G40: 银行自定义。 | H40: C..30 | I40: 删除数据项 | J40: 个人基础信息已有该数据
A41: GYB | B41: 柜员表
C42: 总行机构代码 | D42: ZXJGDM | E42: 银行机构代码 | F42: 001011 | G42: 人行支付行号 | H42: C..30 | I42: 删除数据项 | J42: 非监管关注重点
...
